<?xml version="1.0" ?>


<robot name="my_rb1_robot">

    <!-- Link - chassis -->
    <link name="link_chassis">
        <inertial>
            <origin xyz="0 0 0" rpy="0 0 0"/>
            <mass value="25"/>
            <inertia ixx="0.578125" ixy="0" ixz="0" iyy="0.578125" iyz="0" izz="0.78125"/>
        </inertial>
 
        <visual>
            <origin xyz="0 0 0" rpy="0 0 0"/>
            <geometry>
                <cylinder length=".30" radius=".25"/>
            </geometry>
            <material name="Cyan">
                <color rgba="0 1 0 1"/>
            </material>
        </visual>

        <collision>
            <origin xyz="0 0 0" rpy="0 0 0"/>
            <geometry>
                <cylinder radius=".25" length =".30"/>
            </geometry>
        </collision>
    </link>
        
    <!-- Link-right_wheel -->
    <link name="right_wheel">
        <inertial>
            <origin xyz="0 -.2 -.15"/>
            <inertia ixx=".0025" ixy="0" ixz="0" iyy="0.0025" iyz="0" izz=".005"/>
        </inertial>

        <collision>
            <origin xyz="0 -.2 -.15" rpy="0 0 0"/>
            <geometry>
                <cylinder length="0.025" radius=".025"/>
            </geometry>
        </collision>

        <visual>
            <origin xyz="0 -.2 -.15" rpy"0 0 0"/>
            <geometry>
                <cylinder length=".025" radius=".025"/>
            <geometry>
        </visual>
    </link>
    
    <!-- Link-left_wheel -->
    <link name="left_wheel">
        <inertial>
            <origin xyz="0 .2 -.15"/>
            <inertia ixx=".0025" ixy="0" ixz="0" iyy="0.0025" iyz="0" izz=".005"/>
        </inertial>

        <collision>
            <origin xyz="0 .2 -.15" rpy="0 0 0"/>
            <geometry>
                <cylinder length="0.025" radius=".025"/>
            </geometry>
        </collision>

        <visual>
            <origin xyz="0 .2 -.15" rpy"0 0 0"/>
            <geometry>
                <cylinder length=".025" radius=".025"/>
            <geometry>
        </visual>
    </link>

    <!-- Link-front_caster -->
    <link name="front_caster">
        <collision>
            <origin xyz="=-.1 0 -.15" rpy="0 0 0"/>
            <geometry>
                <sphere radius=".025"/>
            </geometry>
        </collision>

        <visual>
            <origin xyz="-.1 0 -.15" rpy="0 0 0"/>
            <geometry>
                <sphere radius=".025"/>
            </geometry>
            <material name="Grey">
                <color rgba="0.6 0.6 0.6 1"/>
            </material>
        </visual>
    </link>

    <!-- Link-back_caster -->
    <link name="back_caster">
        <collision>
            <origin xyz=".1 0 -.15" rpy="0 0 0"/>
            <geometry>
                <sphere radius=".025"/>
            </geometry>
        </collision>

        <visual>
            <origin xyz=".1 0 -.15" rpy="0 0 0"/>
            <geometry>
                <sphere radius=".025"/>
            </geometry>
            <material name="Grey">
                <color rgba="0.6 0.6 0.6 1"/>
            </material>
        </visual>
    </link>

    <!-- Link-front_laser -->
    <link name="front_laser">
        <collision>
            <origin xyz=".25 0 .075" rpy="180/3.14159 0 0"/>
            <geometry>
                <sphere radius=".001"/>
            </geometry>
        </collison>

        <visual>
            <origin=".25 0 .075" rpy="180/3.14159 0 0"/>
            <geometry>
                <sphere radius=".001"/>
            </geometry>
            <material name="Red">
                <color rgba="1 0 0 1"/>
            </material>
        </visual>
    </link>

    <!-- Link-base_frame -->
    <link name="base_frame">
        <visual>
            <origin xyz="0.0 0.0 0.0" rpy="0.0 0.0 0.0" />
            <geometry>
                <cylinder length="0" radius="0" />
            </geometry>
        </visual>
        <inertial>
            <mass value="0" />
            <origin xyz="0 0 0" />
            <inertia ixx="0" ixy="0" ixz="0" iyy="0" iyz="0" izz="0" />
        </inertial>
    </link>
    
    <!-- Link-base_link -->    
    <link name="base_link">

        <visual>
            <origin xyz="0.0 0.0 0.15" rpy="0.0 0.0 0.0" />
            <geometry>
                <cylinder length="${cylinder_height}" radius="${cylinder_radius}" />
            </geometry>
        </visual>
        <inertial>
            <mass value="0" />
            <origin xyz="0 0 0" />
            <inertia ixx="0" ixy="0" ixz="0" iyy="0" iyz="0" izz="0" />
        </inertial>
    </link>

    <!-- Joint - chassis/right wheel -->
    <joint name="joint_chassis_right_wheel" type="continuous">
        <origin rpy="0 0 0" xyz="-0.5 -0.65 0" />
        <child link="link_right_wheel" />
        <parent link="link_chassis" />
        <axis rpy="0 0 0" xyz="0 1 0" />
        <limit effort="10000" velocity="1000" />
        <joint_properties damping="1.0" friction="1.0" />
    </joint>

    <!-- Joint - chassis/left wheel -->
    <joint name="joint_chassis_left_wheel" type="continuous">
        <origin rpy="0 0 0" xyz="-0.5 0.65 0" />
        <child link="left_wheel" />
        <parent link="link_chassis" />
        <axis rpy="0 0 0" xyz="0 1 0" />
        <limit effort="10000" velocity="1000" />
        <joint_properties damping="1.0" friction="1.0" />
    </joint>

    <!-- Joint - chassis/front_caster -->
    <joint name="joint_chassis_front_caster" type="fixed">
        <origin rpy="0 0 0" xyz="0.8 0 -0.15" />
        <child link="front_caster" />
        <parent link="link_chassis" />
        <joint_properties damping="1.0" friction="1.0" />
    </joint>


    <!-- Joint - chassis/back_caster -->
    <joint name="joint_chassis_back_caster" type="fixed"/>
        <origin rpy="0 0 0" xyz="0.8 0 -0.15" />
        <child link="back_caster" />
        <parent link="link_chassis" />
        <joint_properties damping="1.0" friction="1.0" />
    </joint>

    <!-- Joint - chassis/front_laser -->
    <joint name="joint_chassis_front_laser" type="fixed"/>
</robot>




<!-- just a place holder for code to be tested-->
<!-- Link-front_laser -->
    <link name="front_laser">
        <collision>
            <origin xyz=".25 0 .075" rpy="180/3.14159 0 0"/>
            <geometry>
                <sphere radius=".001"/>
            </geometry>
        </collison>

        <visual>
            <origin=".25 0 .075" rpy="180/3.14159 0 0"/>
            <geometry>
                <sphere radius=".001"/>
            </geometry>
            <material name="Red">
                <color rgba="1 0 0 1"/>
            </material>
        </visual>
        <inertial>
            <mass value="1" />
            <origin xyz="0 0 0" rpy="0 0 0" />
            <inertia ixx="0.002526666666667" ixy="0" ixz="0" iyy="0.002526666666667" iyz="0" izz="0.005"/>
        </inertial>
    </link>

    <!-- Joint-chassis_front_laser -->
    <joint name="joint_chassis_front_laser" type="fixed">
        <origin rpy="3.14159 0 0" xyz=".25 0 .75" />
        <child link="front_laser" />
        <parent link="base_link" />
        <joint_properties damping="1.0" friction="0" />  
    </joint>


    <!-- place holder for part 3 laser coding-->
    <!-- Gazebo tags - Laser scan -->
    <gazebo reference="joint_chassis_front_laser">
        <preserveFixedJoint>true</preserveFixedJoint>
    </gazebo>
    <gazebo reference="front_laser">
        <material>Gazebo/DarkGrey</material>
    </gazebo>

    <!-- Laser scan -->
    <joint name="joint_chassis_front_laser" type="fixed">
        <origin rpy="3.14159 0 0" xyz="0.25 0 0.075" />
        <child link="front_laser" />
        <parent link="base_link" />
        <joint_properties damping="1.0" friction="1.0" />
    </joint>
    <link name="front_laser">
        <inertial>
            <origin xyz="0 0 0" rpy="0 0 0" />
            <mass value="0.5" />
            <inertia ixx="0.000252666666667" ixy="0" ixz="0" iyy="0.000252666666667" iyz="0" izz="0.0005"/>
        </inertial>
        <visual>
            <origin xyz="0 0 0" rpy="0 0 0" />
            <geometry>
                <cylinder radius="0.15" length="0.20"/>
            </geometry>
            <material name="Red">
                <color rgba="0.7 0.1 0.1 1" />
            </material>
        </visual>
        <collision>
            <origin xyz="0 0 0" rpy="0 0 0"/>
            <geometry>
                <cylinder radius="0.15" length="0.20"/>
            </geometry>
        </collision>
    </link>